Workbook

Sheet Ventas
A1: Fecha | B1: Producto | C1: Talla | D1: Cantidad | E1: Precio unitario | F1: Total venta | G1: Total venta | H1: Metodo | I1: Estado
A2: 46279 | B2: Set Negro | C2: L | D2: 1 | E2: 100000 | F2: =IF(AND(D2<>"",E2<>""),D2*E2,"") -> 100000 | G2: =IF(A2<>"",MONTH(A2),"") -> 9 | H2: Pago Anticipado | I2: Pagado
A3: 46280 | B3: Set Beige | C3: M | D3: 1 | E3: 100000 | F3: =IF(AND(D3<>"",E3<>""),D3*E3,"") -> 100000 | G3: =IF(A3<>"",MONTH(A3),"") -> 9 | H3: Pago Anticipado | I3: Pagado
A4: 46281 | B4: Jens Urbano | C4: 34 | D4: 2 | E4: 95000 | F4: =IF(AND(D4<>"",E4<>""),D4*E4,"") -> 190000 | G4: =IF(A4<>"",MONTH(A4),"") -> 9 | H4: Pago Contra-Entrega | I4: No Cancelado
A5: 46281 | B5: Camiseta Urbana 23 | C5: M | D5: 1 | E5: 60000 | F5: =IF(AND(D5<>"",E5<>""),D5*E5,"") -> 60000 | G5: =IF(A5<>"",MONTH(A5),"") -> 9 | H5: Pago Contra-Entrega | I5: No Cancelado
A6: 46282 | B6: Set corto Blanco + Beige | C6: M | D6: 1 | E6: 85000 | F6: =IF(AND(D6<>"",E6<>""),D6*E6,"") -> 85000 | G6: =IF(A6<>"",MONTH(A6),"") -> 9 | H6: Pago Anticipado | I6: Pagado
A7: 46282 | B7: Pantalón caqui | C7: 31 | D7: 1 | E7: 60000 | F7: =IF(AND(D7<>"",E7<>""),D7*E7,"") -> 60000 | G7: =IF(A7<>"",MONTH(A7),"") -> 9 | H7: Pago Anticipado | I7: Pagado
A8: 46282 | B8: Camiseta Vinotinto | C8: M | D8: 1 | E8: 60000 | F8: =IF(AND(D8<>"",E8<>""),D8*E8,"") -> 60000 | G8: =IF(A8<>"",MONTH(A8),"") -> 9 | H8: Pago Anticipado | I8: Pagado
A9: 46282 | B9: Set corto negro | C9: L | D9: 1 | E9: 85000 | F9: =IF(AND(D9<>"",E9<>""),D9*E9,"") -> 85000 | G9: =IF(A9<>"",MONTH(A9),"") -> 9 | H9: Pago Anticipado | I9: No Cancelado
A10: 46283 | B10: Polo negro | C10: L | D10: 1 | E10: 60000 | F10: =IF(AND(D10<>"",E10<>""),D10*E10,"") -> 60000 | G10: =IF(A10<>"",MONTH(A10),"") -> 9 | H10: Pago Anticipado | I10: Pagado
A11: 46283 | B11: Camisa + Pantalón | C11: M | D11: 1 | E11: 100000 | F11: =IF(AND(D11<>"",E11<>""),D11*E11,"") -> 100000 | G11: =IF(A11<>"",MONTH(A11),"") -> 9 | H11: Pago Anticipado | I11: Pagado
A12: 46283 | B12: Camisetas negro | C12: M | D12: 1 | E12: 60000 | F12: =IF(AND(D12<>"",E12<>""),D12*E12,"") -> 60000 | G12: =IF(A12<>"",MONTH(A12),"") -> 9 | H12: Pago Anticipado | I12: Pagado
A13: 46284 | B13: Set corto Beige | C13: L | D13: 1 | E13: 85000 | F13: =IF(AND(D13<>"",E13<>""),D13*E13,"") -> 85000 | G13: =IF(A13<>"",MONTH(A13),"") -> 9 | H13: Pago Anticipado | I13: Pagado
A14: 46284 | B14: Pantalón caqui | C14: 30 | D14: 1 | E14: 60000 | F14: =IF(AND(D14<>"",E14<>""),D14*E14,"") -> 60000 | G14: =IF(A14<>"",MONTH(A14),"") -> 9 | H14: Pago Anticipado | I14: Pagado
A15: 46284 | B15: Camisetas negro | C15: M | D15: 1 | E15: 60000 | F15: =IF(AND(D15<>"",E15<>""),D15*E15,"") -> 60000 | G15: =IF(A15<>"",MONTH(A15),"") -> 9 | H15: Pago Anticipado | I15: Pagado
A16: 46284 | B16: Bermudas de Hombres | C16: 34 | D16: 1 | E16: 90000 | F16: =IF(AND(D16<>"",E16<>""),D16*E16,"") -> 90000 | G16: =IF(A16<>"",MONTH(A16),"") -> 9 | H16: Pago Anticipado | I16: Pagado
F17: =IF(AND(D17<>"",E17<>""),D17*E17,"") | G17: =IF(A17<>"",MONTH(A17),"")
F18: =IF(AND(D18<>"",E18<>""),D18*E18,"") | G18: =IF(A18<>"",MONTH(A18),"")
F19: =IF(AND(D19<>"",E19<>""),D19*E19,"") | G19: =IF(A19<>"",MONTH(A19),"")
F20: =IF(AND(D20<>"",E20<>""),D20*E20,"") | G20: =IF(A20<>"",MONTH(A20),"")
F21: =IF(AND(D21<>"",E21<>""),D21*E21,"") | G21: =IF(A21<>"",MONTH(A21),"") -> #VALUE!
F22: =IF(AND(D22<>"",E22<>""),D22*E22,"") | G22: =IF(A22<>"",MONTH(A22),"")
F23: =IF(AND(D23<>"",E23<>""),D23*E23,"") | G23: =IF(A23<>"",MONTH(A23),"")
F24: =IF(AND(D24<>"",E24<>""),D24*E24,"") | G24: =IF(A24<>"",MONTH(A24),"")
F25: =IF(AND(D25<>"",E25<>""),D25*E25,"") | G25: =IF(A25<>"",MONTH(A25),"")
F26: =IF(AND(D26<>"",E26<>""),D26*E26,"") | G26: =IF(A26<>"",MONTH(A26),"")
F27: =IF(AND(D27<>"",E27<>""),D27*E27,"") | G27: =IF(A27<>"",MONTH(A27),"")
F28: =IF(AND(D28<>"",E28<>""),D28*E28,"") | G28: =IF(A28<>"",MONTH(A28),"")
... F291: =IF(AND(D291<>"",E291<>""),D291*E291,"") | G291: =IF(A291<>"",MONTH(A291),"")
A293: Cómo usar esta hoja:
A294: Escribe cada venta en una fila nueva (Fecha, Producto, Talla, Cantidad, Precio unitario). La fila 2 es un ejemplo, bórrala o edítala.
A295: La columna Total venta se calcula sola.

Sheet Resumen
A1: RESUMEN DE VENTAS
A3: Total general vendido | B3: =SUM(Ventas!F2:F291) -> 1255000
A5: Ventas por mes
A6: Mes | B6: Total vendido
A7: Enero | B7: =SUMIFS(Ventas!$F$2:$F$291,Ventas!$G$2:$G$291,1) -> 0
A8: Febrero | B8: =SUMIFS(Ventas!$F$2:$F$291,Ventas!$G$2:$G$291,2) -> 0
A9: Marzo | B9: =SUMIFS(Ventas!$F$2:$F$291,Ventas!$G$2:$G$291,3) -> 0
A10: Abril | B10: =SUMIFS(Ventas!$F$2:$F$291,Ventas!$G$2:$G$291,4) -> 0
A11: Mayo | B11: =SUMIFS(Ventas!$F$2:$F$291,Ventas!$G$2:$G$291,5) -> 0
A12: Junio | B12: =SUMIFS(Ventas!$F$2:$F$291,Ventas!$G$2:$G$291,6) -> 0
A13: Julio | B13: =SUMIFS(Ventas!$F$2:$F$291,Ventas!$G$2:$G$291,7) -> 0
A14: Agosto | B14: =SUMIFS(Ventas!$F$2:$F$291,Ventas!$G$2:$G$291,8) -> 0
A15: Septiembre | B15: =SUMIFS(Ventas!$F$2:$F$291,Ventas!$G$2:$G$291,9) -> 1255000
A16: Octubre | B16: =SUMIFS(Ventas!$F$2:$F$291,Ventas!$G$2:$G$291,10) -> 0
A17: Noviembre | B17: =SUMIFS(Ventas!$F$2:$F$291,Ventas!$G$2:$G$291,11) -> 0
A18: Diciembre | B18: =SUMIFS(Ventas!$F$2:$F$291,Ventas!$G$2:$G$291,12) -> 0
A20: Ventas por producto
A21: Producto | B21: Cantidad vendida | C21: Total vendido
A22: Polo negro | B22: =SUMIFS(Ventas!$D$2:$D$291,Ventas!$B$2:$B$291,A22) -> 1 | C22: =SUMIFS(Ventas!$F$2:$F$291,Ventas!$B$2:$B$291,A22) -> 60000
A23: Polo Blanco | B23: =SUMIFS(Ventas!$D$2:$D$291,Ventas!$B$2:$B$291,A23) -> 0 | C23: =SUMIFS(Ventas!$F$2:$F$291,Ventas!$B$2:$B$291,A23) -> 0
A24: Jens Urbano | B24: =SUMIFS(Ventas!$D$2:$D$291,Ventas!$B$2:$B$291,A24) -> 2 | C24: =SUMIFS(Ventas!$F$2:$F$291,Ventas!$B$2:$B$291,A24) -> 190000
A25: Camiseta Urbana 23 | B25: =SUMIFS(Ventas!$D$2:$D$291,Ventas!$B$2:$B$291,A25) -> 1 | C25: =SUMIFS(Ventas!$F$2:$F$291,Ventas!$B$2:$B$291,A25) -> 60000
A26: Set Rojo | B26: =SUMIFS(Ventas!$D$2:$D$291,Ventas!$B$2:$B$291,A26) -> 0 | C26: =SUMIFS(Ventas!$F$2:$F$291,Ventas!$B$2:$B$291,A26) -> 0
A27: Polo + Pantalón | B27: =SUMIFS(Ventas!$D$2:$D$291,Ventas!$B$2:$B$291,A27) -> 0 | C27: =SUMIFS(Ventas!$F$2:$F$291,Ventas!$B$2:$B$291,A27) -> 0
A28: Camisa + Pantalón | B28: =SUMIFS(Ventas!$D$2:$D$291,Ventas!$B$2:$B$291,A28) -> 1 | C28: =SUMIFS(Ventas!$F$2:$F$291,Ventas!$B$2:$B$291,A28) -> 100000
A29: Set Beige | B29: =SUMIFS(Ventas!$D$2:$D$291,Ventas!$B$2:$B$291,A29) -> 1 | C29: =SUMIFS(Ventas!$F$2:$F$291,Ventas!$B$2:$B$291,A29) -> 100000
A30: Set corto negro | B30: =SUMIFS(Ventas!$D$2:$D$291,Ventas!$B$2:$B$291,A30) -> 1 | C30: =SUMIFS(Ventas!$F$2:$F$291,Ventas!$B$2:$B$291,A30) -> 85000
A31: Set Negro | B31: =SUMIFS(Ventas!$D$2:$D$291,Ventas!$B$2:$B$291,A31) -> 1 | C31: =SUMIFS(Ventas!$F$2:$F$291,Ventas!$B$2:$B$291,A31) -> 100000
A32: Set corto Beige | B32: =SUMIFS(Ventas!$D$2:$D$291,Ventas!$B$2:$B$291,A32) -> 1 | C32: =SUMIFS(Ventas!$F$2:$F$291,Ventas!$B$2:$B$291,A32) -> 85000
A33: Camiseta Urbana Azul | B33: =SUMIFS(Ventas!$D$2:$D$291,Ventas!$B$2:$B$291,A33) -> 0 | C33: =SUMIFS(Ventas!$F$2:$F$291,Ventas!$B$2:$B$291,A33) -> 0
... A44: Camiseta Vinotinto | B44: =SUMIFS(Ventas!$D$2:$D$291,Ventas!$B$2:$B$291,A44) -> 1 | C44: =SUMIFS(Ventas!$F$2:$F$291,Ventas!$B$2:$B$291,A44) -> 60000
A45: TOTAL | B45: =SUM(B22:B44) -> 16 | C45: =SUM(C22:C44) -> 1255000
A47: Ventas por semana
A48: Semana (inicio, lunes) | B48: Semana (fin, domingo) | C48: Total vendido
A49: =IF(COUNT(Ventas!$A$2:$A$291)>0,MIN(Ventas!$A$2:$A$291)-WEEKDAY(MIN(Ventas!$A$2:$A$291),3),TODAY()-WEEKDAY(TODAY(),3)) -> 46279 | B49: =A49+6 -> 46285 | C49: =SUMIFS(Ventas!$F$2:$F$291,Ventas!$A$2:$A$291,">="&A49,Ventas!$A$2:$A$291,"<="&B49) -> 1255000
A50: =A49+7 -> 46286 | B50: =A50+6 -> 46292 | C50: =SUMIFS(Ventas!$F$2:$F$291,Ventas!$A$2:$A$291,">="&A50,Ventas!$A$2:$A$291,"<="&B50) -> 0
A51: =A50+7 -> 46293 | B51: =A51+6 -> 46299 | C51: =SUMIFS(Ventas!$F$2:$F$291,Ventas!$A$2:$A$291,">="&A51,Ventas!$A$2:$A$291,"<="&B51) -> 0
A52: =A51+7 -> 46300 | B52: =A52+6 -> 46306 | C52: =SUMIFS(Ventas!$F$2:$F$291,Ventas!$A$2:$A$291,">="&A52,Ventas!$A$2:$A$291,"<="&B52) -> 0
A53: =A52+7 -> 46307 | B53: =A53+6 -> 46313 | C53: =SUMIFS(Ventas!$F$2:$F$291,Ventas!$A$2:$A$291,">="&A53,Ventas!$A$2:$A$291,"<="&B53) -> 0
A54: =A53+7 -> 46314 | B54: =A54+6 -> 46320 | C54: =SUMIFS(Ventas!$F$2:$F$291,Ventas!$A$2:$A$291,">="&A54,Ventas!$A$2:$A$291,"<="&B54) -> 0
...

Sheet Compras y Pendientes
A1: Estado | B1: Descripción | C1: Proveedor | D1: Fecha | E1: Costo | F1: Notas
A2: Comprado | B2: 13 Set Corto Negro 1 S - 5 M - 3 L - 3 XL - 1 XXL | C2: TEMU | D2: 46279 | E2: 395519 | F2: RENOVAR INVENTARIO
A3: Comprado | B3: 9 Set Corto Beige 1 S - 5 M - 2 XL - 1 XXL | C3: TEMU | D3: 46280 | E3: 275904 | F3: RENOVAR INVENTARIO
A201: Total pendiente por comprar | E201: =SUMIFS(E2:E199,A2:A199,"Pendiente") -> 0
A202: Total ya comprado | E202: =SUMIFS(E2:E199,A2:A199,"Comprado") -> 671423
A204: Cómo usar esta hoja:
A205: Anota aquí cualquier prenda o insumo que necesites comprar, aunque no tengas el costo exacto todavía. Marca "Pendiente" mientras lo compras y cámbialo a "Comprado" cuando ya lo tengas. La fila 2 es un ejemplo.

Sheet Gastos
A1: Fecha | B1: Categoría | C1: Descripción | D1: Monto | F1: Mes (auxiliar)
A2: 46279 | B2: Prestamo | C2: Completar pedido - 9 Set Corto Beige | D2: 27400 | F2: =IF(A2<>"",MONTH(A2),"") -> 9
F3: =IF(A3<>"",MONTH(A3),"")
F4: =IF(A4<>"",MONTH(A4),"")
F5: =IF(A5<>"",MONTH(A5),"")
F6: =IF(A6<>"",MONTH(A6),"")
F7: =IF(A7<>"",MONTH(A7),"")
F8: =IF(A8<>"",MONTH(A8),"")
F9: =IF(A9<>"",MONTH(A9),"")
F10: =IF(A10<>"",MONTH(A10),"")
F11: =IF(A11<>"",MONTH(A11),"")
F12: =IF(A12<>"",MONTH(A12),"")
F13: =IF(A13<>"",MONTH(A13),"")
F14: =IF(A14<>"",MONTH(A14),"")
... F299: =IF(A299<>"",MONTH(A299),"")
A301: TOTAL GASTADO | D301: =SUM(D2:D299) -> 27400
A303: Cómo usar esta hoja:
A304: Registra aquí cualquier salida de dinero de la cuenta del negocio (compra de mercancía, arriendo, servicios, transporte, etc.). La fila 2 es un ejemplo.
